Workbook

Sheet 汇总表1月-4月
A1: 2025年1-4月员工加班小时数汇总（按项目组）
A2: BU | B2: 项目组 | C2: 加班总小时数（1-4月） | D2: 月均在职人数（1-4月） | E2: 人均加班小时数（1-4月） | F2: 1月 | I2: 2月 | L2: 3月 | O2: 4月 | R2: 备注
F3: 加班总小时数 | G3: 月在职人数 | H3: 月人均加班小时数 | I3: 加班总小时数 | J3: 月在职人数 | K3: 月人均加班小时数 | L3: 加班总小时数 | M3: 月在职人数 | N3: 月人均加班小时数 | O3: 加班总小时数 | P3: 月在职人数 | Q3: 月人均加班小时数
A4: 慧税云服 | B4: 慧税学苑-产品研发组 | C4: =F4+I4+L4+O4 -> 13.95625 | D4: =ROUND((G4+J4+M4+P4)/4,0) -> 11 | E4: =C4/D4 -> 1.26875 | F4: 0.87291667 | G4: 11 | H4: =F4/G4 -> 0.079356061 | I4: 0.63333333 | J4: 11 | K4: =I4/J4 -> 0.057575758 | L4: =VLOOKUP(B4,[1]筛选后!$S$4:$T$14,2,0) -> 4.5868056 | M4: 11 | N4: =L4/M4 -> 0.41698232 | O4: 7.8631944 | P4: 11 | Q4: =O4/P4 -> 0.71483586
B5: 慧税学苑-教研组 | C5: =F5+I5+L5+O5 -> 2.4076389 | D5: =ROUND((G5+J5+M5+P5)/4,0) -> 9 | E5: =C5/D5 -> 0.26751543 | F5: 0.25486111 | G5: 9 | H5: =F5/G5 -> 0.028317901 | I5: 0.22430556 | J5: 9 | K5: =I5/J5 -> 0.02492284 | L5: =VLOOKUP(B5,[1]筛选后!$S$4:$T$14,2,0) -> 0.82361111 | M5: 9 | N5: =L5/M5 -> 0.091512346 | O5: 1.1048611 | P5: 9 | Q5: =O5/P5 -> 0.12276235
B6: 慧税学苑-运营组 | C6: =F6+I6+L6+O6 -> 1.5673611 | D6: =ROUND((G6+J6+M6+P6)/4,0) -> 2 | E6: =C6/D6 -> 0.78368056 | F6: 0.50138889 | G6: 2 | H6: =F6/G6 -> 0.25069444 | I6: 0.15833333 | J6: 2 | K6: =I6/J6 -> 0.079166667 | L6: =VLOOKUP(B6,[1]筛选后!$S$4:$T$14,2,0) -> 0.62777778 | M6: 2 | N6: =L6/M6 -> 0.31388889 | O6: 0.27986111 | P6: 2 | Q6: =O6/P6 -> 0.13993056
B7: 慧税学苑-品牌组 | C7: =F7+I7+L7+O7 -> 0.28263889 | D7: =ROUND((G7+J7+M7+P7)/4,0) -> 1 | E7: =C7/D7 -> 0.28263889 | F7: 0.14236111 | G7: 1 | H7: =F7/G7 -> 0.14236111 | I7: 0 | J7: 1 | K7: =I7/J7 -> 0 | L7: 0 | M7: 1 | N7: =L7/M7 -> 0 | O7: 0.14027778 | P7: 1 | Q7: =O7/P7 -> 0.14027778
A8: 税企服务中心 | B8: B端服务组 | C8: =F8+I8+L8+O8 -> 10.888194 | D8: =ROUND((G8+J8+M8+P8)/4,0) -> 27 | E8: =C8/D8 -> 0.40326646 | F8: 1.8569444 | G8: 27 | H8: =F8/G8 -> 0.06877572 | I8: 1.3270833 | J8: 27 | K8: =I8/J8 -> 0.049151235 | L8: =VLOOKUP(B8,[1]筛选后!$S$4:$T$14,2,0) -> 4.0020833 | M8: 27 | N8: =L8/M8 -> 0.14822531 | O8: 3.7020833 | P8: 27 | Q8: =O8/P8 -> 0.1371142
B9: G端服务组 | C9: =F9+I9+L9+O9 -> 5.9270833 | D9: =ROUND((G9+J9+M9+P9)/4,0) -> 16 | E9: =C9/D9 -> 0.37044271 | F9: 1.7840278 | G9: 16 | H9: =F9/G9 -> 0.11150174 | I9: 0.84930556 | J9: 16 | K9: =I9/J9 -> 0.053081597 | L9: =VLOOKUP(B9,[1]筛选后!$S$4:$T$14,2,0) -> 1.8180556 | M9: 16 | N9: =L9/M9 -> 0.11362847 | O9: 1.4756944 | P9: 15 | Q9: =O9/P9 -> 0.09837963
B10: 资源中心-资源组 | C10: =F10+I10+L10+O10 -> 2.9548611 | D10: =ROUND((G10+J10+M10+P10)/4,0) -> 18 | E10: =C10/D10 -> 0.16415895 | F10: 0.55694444 | G10: 18 | H10: =F10/G10 -> 0.030941358 | I10: 0.79166667 | J10: 18 | K10: =I10/J10 -> 0.043981481 | L10: =VLOOKUP(B10,[1]筛选后!$S$4:$T$14,2,0) -> 0.46180556 | M10: 18 | N10: =L10/M10 -> 0.025655864 | O10: 1.1444444 | P10: 18 | Q10: =O10/P10 -> 0.063580247
B11: 资源中心-数据组 | C11: =F11+I11+L11+O11 -> 0.27083333 | D11: =ROUND((G11+J11+M11+P11)/4,0) -> 4 | E11: =C11/D11 -> 0.067708333 | F11: 0 | G11: 4 | H11: =F11/G11 -> 0 | I11: 0 | J11: 4 | K11: =I11/J11 -> 0 | L11: =VLOOKUP(B11,[1]筛选后!$S$4:$T$14,2,0) -> 0.27083333 | M11: 4 | N11: =L11/M11 -> 0.067708333 | O11: 0 | P11: 4 | Q11: =O11/P11 -> 0
B12: 资源中心-架构组 | C12: =F12+I12+L12+O12 -> 0.15208333 | D12: =ROUND((G12+J12+M12+P12)/4,0) -> 2 | E12: =C12/D12 -> 0.076041667 | F12: 0.050694444 | G12: 2 | H12: =F12/G12 -> 0.025347222 | I12: 0 | J12: 2 | K12: =I12/J12 -> 0 | L12: =VLOOKUP(B12,[1]筛选后!$S$4:$T$14,2,0) -> 0.049305556 | M12: 2 | N12: =L12/M12 -> 0.024652778 | O12: 0.052083333 | P12: 2 | Q12: =O12/P12 -> 0.026041667
A13: 商务法务部 | B13: 商务法务部 | C13: =F13+I13+L13+O13 -> 1.0263889 | D13: =ROUND((G13+J13+M13+P13)/4,0) -> 2 | E13: =C13/D13 -> 0.51319444 | F13: 0.30416667 | G13: 2 | H13: =F13/G13 -> 0.15208333 | I13: 0 | J13: 2 | K13: =I13/J13 -> 0 | L13: =VLOOKUP(B13,[1]筛选后!$S$4:$T$14,2,0) -> 0.62708333 | M13: 2 | N13: =L13/M13 -> 0.31354167 | O13: 0.095138889 | P13: 2 | Q13: =O13/P13 -> 0.047569444
A14: 项目管理办公室 | B14: 项目管理办公室 | C14: =F14+I14+L14+O14 -> 0 | D14: =ROUND((G14+J14+M14+P14)/4,0) -> 1 | E14: =C14/D14 -> 0 | F14: 0 | G14: 1 | H14: =F14/G14 -> 0 | I14: 0 | J14: 1 | K14: =I14/J14 -> 0 | L14: 0 | M14: 1 | N14: =L14/M14 -> 0 | O14: 0 | P14: 1 | Q14: =O14/P14 -> 0
A15: 财务部 | B15: 财务部 | C15: =F15+I15+L15+O15 -> 0 | D15: =ROUND((G15+J15+M15+P15)/4,0) -> 3 | E15: =C15/D15 -> 0 | F15: 0 | G15: 3 | H15: =F15/G15 -> 0 | I15: 0 | J15: 3 | K15: =I15/J15 -> 0 | L15: 0 | M15: 3 | N15: =L15/M15 -> 0 | O15: 0 | P15: 3 | Q15: =O15/P15 -> 0
A16: IT服务部 | B16: IT服务部 | C16: =F16+I16+L16+O16 -> 1.2 | D16: =ROUND((G16+J16+M16+P16)/4,0) -> 1 | E16: =C16/D16 -> 1.2 | F16: 0 | G16: 1 | H16: =F16/G16 -> 0 | I16: 0 | J16: 1 | K16: =I16/J16 -> 0 | L16: =VLOOKUP(B16,[1]筛选后!$S$4:$T$14,2,0) -> 1.2 | M16: 1 | N16: =L16/M16 -> 1.2 | O16: 0 | P16: 1 | Q16: =O16/P16 -> 0
A17: 人力资源&行政部 | B17: 人力资源&行政部 | C17: =F17+I17+L17+O17 -> 0.67430556 | D17: =ROUND((G17+J17+M17+P17)/4,0) -> 2 | E17: =C17/D17 -> 0.33715278 | F17: 0.082638889 | G17: 2 | H17: =F17/G17 -> 0.041319444 | I17: 0 | J17: 2 | K17: =I17/J17 -> 0 | L17: =VLOOKUP(B17,[1]筛选后!$S$4:$T$14,2,0) -> 0.44027778 | M17: 2 | N17: =L17/M17 -> 0.22013889 | O17: 0.15138889 | P17: 2 | Q17: =O17/P17 -> 0.075694444
A18: 合计 | C18: =SUM(C4:C17) -> 41.307639 | D18: =SUM(D4:D17) -> 99 | E18: =C18/D18 -> 0.41724888 | F18: =SUM(F4:F17) -> 6.4069444 | G18: =SUM(G4:G17) -> 99 | H18: =F18/G18 -> 0.064716611 | I18: =SUM(I4:I17) -> 3.9840278 | J18: =SUM(J4:J17) -> 99 | K18: =I18/J18 -> 0.040242705 | L18: =SUM(L4:L17) -> 14.907639 | M18: =SUM(M4:M17) -> 99 | N18: =L18/M18 -> 0.15058221 | O18: =SUM(O4:O17) -> 16.009028 | P18: =SUM(P4:P17) -> 98 | Q18: =O18/P18 -> 0.16335743
A19: 备注：加班1小时起计算，不满1小时不计入加班。
A40: 2025年1-4月人均加班小时数汇总（按项目组）
A41: BU | B41: 项目组 | C41: 1月人均加班小时数 | D41: 2月人均加班小时数 | E41: 3月人均加班小时数 | F41: 4月人均加班小时数
A42: 慧税云服 | B42: 慧税学苑-产品研发组 | C42: =H4 -> 0.079356061 | D42: =K4 -> 0.057575758 | E42: =N4 -> 0.41698232 | F42: =Q4 -> 0.71483586
B43: 慧税学苑-教研组 | C43: =H5 -> 0.028317901 | D43: =K5 -> 0.02492284 | E43: =N5 -> 0.091512346 | F43: =Q5 -> 0.12276235
B44: 慧税学苑-运营组 | C44: =H6 -> 0.25069444 | D44: =K6 -> 0.079166667 | E44: =N6 -> 0.31388889 | F44: =Q6 -> 0.13993056
B45: 慧税学苑-品牌组 | C45: =H7 -> 0.14236111 | D45: =K7 -> 0 | E45: =N7 -> 0 | F45: =Q7 -> 0.14027778
A46: 税企服务中心 | B46: B端服务组 | C46: =H8 -> 0.06877572 | D46: =K8 -> 0.049151235 | E46: =N8 -> 0.14822531 | F46: =Q8 -> 0.1371142
B47: G端服务组 | C47: =H9 -> 0.11150174 | D47: =K9 -> 0.053081597 | E47: =N9 -> 0.11362847 | F47: =Q9 -> 0.09837963
B48: 资源中心-资源组 | C48: =H10 -> 0.030941358 | D48: =K10 -> 0.043981481 | E48: =N10 -> 0.025655864 | F48: =Q10 -> 0.063580247
B49: 资源中心-数据组 | C49: =H11 -> 0 | D49: =K11 -> 0 | E49: =N11 -> 0.067708333 | F49: =Q11 -> 0
B50: 资源中心-架构组 | C50: =H12 -> 0.025347222 | D50: =K12 -> 0 | E50: =N12 -> 0.024652778 | F50: =Q12 -> 0.026041667
A51: 商务法务部 | B51: 商务法务部 | C51: =H13 -> 0.15208333 | D51: =K13 -> 0 | E51: =N13 -> 0.31354167 | F51: =Q13 -> 0.047569444
A52: 项目管理办公室 | B52: 项目管理办公室 | C52: =H14 -> 0 | D52: =K14 -> 0 | E52: =N14 -> 0 | F52: =Q14 -> 0
A53: 财务部 | B53: 财务部 | C53: =H15 -> 0 | D53: =K15 -> 0 | E53: =N15 -> 0 | F53: =Q15 -> 0
A54: IT服务部 | B54: IT服务部 | C54: =H16 -> 0 | D54: =K16 -> 0 | E54: =N16 -> 1.2 | F54: =Q16 -> 0
A55: 人力资源&行政部 | B55: 人力资源&行政部 | C55: =H17 -> 0.041319444 | D55: =K17 -> 0 | E55: =N17 -> 0.22013889 | F55: =Q17 -> 0.075694444
A56: 合计 | C56: =H18 -> 0.064716611 | D56: =K18 -> 0.040242705 | E56: =N18 -> 0.15058221 | F56: =Q18 -> 0.16335743
A59: 2025年1-4月员工加班小时数汇总（按BU）
A60: BU | B60: 加班总小时数 | C60: 月均在职人数 | D60: 人均加班小时数
A61: 慧税云服 | B61: =SUM(C4:C7) -> 18.213889 | C61: =SUM(D4:D7) -> 23 | D61: =B61/C61 -> 0.79190821
A62: 税企服务中心 | B62: =SUM(C8:C12) -> 20.193056 | C62: =SUM(D8:D12) -> 67 | D62: =B62/C62 -> 0.30138889
...

Sheet 1月加班排序表
A1: 2025年1月员工加班排序（按加班小时数）
A2: 序号 | B2: 员工姓名 | C2: BU名称 | D2: 项目组 | E2: 加班总小时数 | F2: 加班总频次 | G2: 平均单频加班小时数 | H2: 备注
A3: 1 | B3: 王连城 | C3: 税企服务中心 | D3: G端服务组 | E3: 0.81458333 | F3: 7 | G3: =E3/F3 -> 0.11636905
A4: 2 | B4: 张琪 | C4: 税企服务中心 | D4: B端服务组 | E4: 0.77152778 | F4: 3 | G4: =E4/F4 -> 0.25717593
A5: 3 | B5: 方应广 | C5: 慧税云服 | D5: 慧税学苑-产品研发组 | E5: 0.57916667 | F5: 8 | G5: =E5/F5 -> 0.072395833
A6: 4 | B6: 牟嘉文 | C6: 税企服务中心 | D6: G端服务组 | E6: 0.39513889 | F6: 5 | G6: =E6/F6 -> 0.079027778
A7: 5 | B7: 李超 | C7: 商务法务部 | D7: 商务法务部 | E7: 0.30416667 | F7: 3 | G7: =E7/F7 -> 0.10138889
A8: 6 | B8: 张思思 | C8: 税企服务中心 | D8: B端服务组 | E8: 0.28472222 | F8: 4 | G8: =E8/F8 -> 0.071180556
A9: 7 | B9: 孙健 | C9: 慧税云服 | D9: 慧税学苑-运营组 | E9: 0.25347222 | F9: 4 | G9: =E9/F9 -> 0.063368056
A10: 8 | B10: 陈芊彤 | C10: 慧税云服 | D10: 慧税学苑-运营组 | E10: 0.24791667 | F10: 4 | G10: =E10/F10 -> 0.061979167
A11: 9 | B11: 赵秋磊 | C11: 税企服务中心 | D11: B端服务组 | E11: 0.21736111 | F11: 5 | G11: =E11/F11 -> 0.043472222
A12: 10 | B12: 张传林 | C12: 慧税云服 | D12: 慧税学苑-产品研发组 | E12: 0.19930556 | F12: 3 | G12: =E12/F12 -> 0.066435185
A13: 11 | B13: 张慧艳 | C13: 税企服务中心 | D13: 资源中心-资源组 | E13: 0.1875 | F13: 4 | G13: =E13/F13 -> 0.046875
A14: 12 | B14: 李艳婷 | C14: 慧税云服 | D14: 慧税学苑-教研组 | E14: 0.16805556 | F14: 2 | G14: =E14/F14 -> 0.084027778
... A34: 32 | B34: 李海龙 | C34: 税企服务中心 | D34: B端服务组 | E34: 0.043055556 | F34: 1 | G34: =E34/F34 -> 0.043055556

Sheet 2月加班排序表
A1: 2025年2月员工加班排序（按加班小时数）
A2: 序号 | B2: 员工姓名 | C2: BU名称 | D2: 项目组 | E2: 加班总小时数 | F2: 加班总频次 | G2: 平均单频加班小时数 | H2: 备注
A3: 1 | B3: 张琪 | C3: 税企服务中心 | D3: B端服务组 | E3: 0.44513889 | F3: 5 | G3: =E3/F3 -> 0.089027778
A4: 2 | B4: 王连城 | C4: 税企服务中心 | D4: G端服务组 | E4: 0.40069444 | F4: 3 | G4: =E4/F4 -> 0.13356481
A5: 3 | B5: 张慧艳 | C5: 税企服务中心 | D5: 资源中心-资源组 | E5: 0.28194444 | F5: 4 | G5: =E5/F5 -> 0.070486111
A6: 4 | B6: 汪子洋 | C6: 税企服务中心 | D6: 资源中心-资源组 | E6: 0.2375 | F6: 2 | G6: =E6/F6 -> 0.11875
A7: 5 | B7: 方应广 | C7: 慧税云服 | D7: 慧税学苑-产品研发组 | E7: 0.23541667 | F7: 4 | G7: =E7/F7 -> 0.058854167
A8: 6 | B8: 李艳婷 | C8: 慧税云服 | D8: 慧税学苑-教研组 | E8: 0.18263889 | F8: 2 | G8: =E8/F8 -> 0.091319444
A9: 7 | B9: 毛志鹏 | C9: 税企服务中心 | D9: B端服务组 | E9: 0.18055556 | F9: 1 | G9: =E9/F9 -> 0.18055556
A10: 8 | B10: 赵秋磊 | C10: 税企服务中心 | D10: B端服务组 | E10: 0.17013889 | F10: 4 | G10: =E10/F10 -> 0.042534722
A11: 9 | B11: 刘强 | C11: 税企服务中心 | D11: G端服务组 | E11: 0.16041667 | F11: 2 | G11: =E11/F11 -> 0.080208333
A12: 10 | B12: 陈芊彤 | C12: 慧税云服 | D12: 慧税学苑-运营组 | E12: 0.15833333 | F12: 2 | G12: =E12/F12 -> 0.079166667
A13: 11 | B13: 张传林 | C13: 慧税云服 | D13: 慧税学苑-产品研发组 | E13: 0.15694444 | F13: 2 | G13: =E13/F13 -> 0.078472222
A14: 12 | B14: 孙云龙 | C14: 税企服务中心 | D14: G端服务组 | E14: 0.14722222 | F14: 1 | G14: =E14/F14 -> 0.14722222
... A31: 29 | B31: 王小玢 | C31: 慧税云服 | D31: 慧税学苑-教研组 | E31: 0.041666667 | F31: 1 | G31: =E31/F31 -> 0.041666667

Sheet 3月加班排序表
A1: 2025年3月员工加班排序（按加班小时数）
A2: 序号 | B2: 员工姓名 | C2: BU名称 | D2: 项目组 | E2: 加班总小时数 | F2: 加班总频次 | G2: 平均单频加班小时数 | H2: 备注
A3: 1 | B3: 张传林 | C3: 慧税云服 | D3: 慧税学苑-产品研发组 | E3: 1.3041667 | F3: 9 | G3: =E3/F3 -> 0.14490741
A4: 2 | B4: 蒋本乐 | C4: 总经办 | D4: IT服务部 | E4: 1.2 | F4: 4 | G4: =E4/F4 -> 0.3
A5: 3 | B5: 张思思 | C5: 税企服务中心 | D5: B端服务组 | E5: 0.76111111 | F5: 8 | G5: =E5/F5 -> 0.095138889
A6: 4 | B6: 钟新宇 | C6: 慧税云服 | D6: 慧税学苑-产品研发组 | E6: 0.65486111 | F6: 5 | G6: =E6/F6 -> 0.13097222
A7: 5 | B7: 李艳婷 | C7: 慧税云服 | D7: 慧税学苑-教研组 | E7: 0.63055556 | F7: 6 | G7: =E7/F7 -> 0.10509259
A8: 6 | B8: 王连城 | C8: 税企服务中心 | D8: G端服务组 | E8: 0.57986111 | F8: 4 | G8: =E8/F8 -> 0.14496528
A9: 7 | B9: 陈秋阳 | C9: 税企服务中心 | D9: B端服务组 | E9: 0.52222222 | F9: 10 | G9: =E9/F9 -> 0.052222222
A10: 8 | B10: 孙健 | C10: 慧税云服 | D10: 慧税学苑-运营组 | E10: 0.41458333 | F10: 4 | G10: =E10/F10 -> 0.10364583
A11: 9 | B11: 郝帅 | C11: 慧税云服 | D11: 慧税学苑-产品研发组 | E11: 0.41041667 | F11: 6 | G11: =E11/F11 -> 0.068402778
A12: 10 | B12: 刘天明 | C12: 慧税云服 | D12: 慧税学苑-产品研发组 | E12: 0.38611111 | F12: 5 | G12: =E12/F12 -> 0.077222222
A13: 11 | B13: 单珊 | C13: 人力资源&行政部 | D13: 人力资源&行政部 | E13: 0.34861111 | F13: 2 | G13: =E13/F13 -> 0.17430556
A14: 12 | B14: 张权中 | C14: 慧税云服 | D14: 慧税学苑-产品研发组 | E14: 0.34583333 | F14: 5 | G14: =E14/F14 -> 0.069166667
... A59: 57 | B59: 单国枫 | C59: 税企服务中心 | D59: B端服务组 | E59: 0.042361111 | F59: 1 | G59: =E59/F59 -> 0.042361111

Sheet 4月加班排序表 
A1: 2025年4月员工加班排序（按加班小时数）
A2: 序号 | B2: 员工姓名 | C2: BU名称 | D2: 项目组 | E2: 加班总小时数 | F2: 加班总频次 | G2: 平均单频加班小时数 | H2: 备注
A3: 1 | B3: 郝帅 | C3: =VLOOKUP(B3,[2]Sheet2!$B:$F,5,0) -> 慧税云服 | D3: =VLOOKUP(B3,[2]Sheet2!$B:$H,7,0) -> 慧税学苑-产品研发组 | E3: 1.0583333 | F3: 15 | G3: =E3/F3 -> 0.070555556 | J3: 行标签 | K3: 求和项:加班总小时数
A4: 2 | B4: 刘天明 | C4: =VLOOKUP(B4,[2]Sheet2!$B:$F,5,0) -> 慧税云服 | D4: =VLOOKUP(B4,[2]Sheet2!$B:$H,7,0) -> 慧税学苑-产品研发组 | E4: 1.0520833 | F4: 15 | G4: =E4/F4 -> 0.070138889 | J4: B端服务组 | K4: 3.7020833
A5: 3 | B5: 李艳婷 | C5: =VLOOKUP(B5,[2]Sheet2!$B:$F,5,0) -> 慧税云服 | D5: =VLOOKUP(B5,[2]Sheet2!$B:$H,7,0) -> 慧税学苑-教研组 | E5: 1.0444444 | F5: 12 | G5: =E5/F5 -> 0.087037037 | J5: G端服务组 | K5: 1.4756944
A6: 4 | B6: 张传林 | C6: =VLOOKUP(B6,[2]Sheet2!$B:$F,5,0) -> 慧税云服 | D6: =VLOOKUP(B6,[2]Sheet2!$B:$H,7,0) -> 慧税学苑-产品研发组 | E6: 1.0027778 | F6: 14 | G6: =E6/F6 -> 0.071626984 | J6: 慧税学苑-产品研发组 | K6: 7.8631944
A7: 5 | B7: 郝军 | C7: =VLOOKUP(B7,[2]Sheet2!$B:$F,5,0) -> 慧税云服 | D7: =VLOOKUP(B7,[2]Sheet2!$B:$H,7,0) -> 慧税学苑-产品研发组 | E7: 0.91875 | F7: 14 | G7: =E7/F7 -> 0.065625 | J7: 慧税学苑-教研组 | K7: 1.1048611
A8: 6 | B8: 陈秋阳 | C8: =VLOOKUP(B8,[2]Sheet2!$B:$F,5,0) -> 税企服务中心 | D8: =VLOOKUP(B8,[2]Sheet2!$B:$H,7,0) -> B端服务组 | E8: 0.83263889 | F8: 16 | G8: =E8/F8 -> 0.052039931 | J8: 慧税学苑-品牌组 | K8: 0.14027778
A9: 7 | B9: 钟新宇 | C9: =VLOOKUP(B9,[2]Sheet2!$B:$F,5,0) -> 慧税云服 | D9: =VLOOKUP(B9,[2]Sheet2!$B:$H,7,0) -> 慧税学苑-产品研发组 | E9: 0.82430556 | F9: 13 | G9: =E9/F9 -> 0.06340812 | J9: 慧税学苑-运营组 | K9: 0.27986111
A10: 8 | B10: 徐友 | C10: =VLOOKUP(B10,[2]Sheet2!$B:$F,5,0) -> 慧税云服 | D10: =VLOOKUP(B10,[2]Sheet2!$B:$H,7,0) -> 慧税学苑-产品研发组 | E10: 0.82222222 | F10: 13 | G10: =E10/F10 -> 0.063247863 | J10: 人力资源&行政部 | K10: 0.15138889
A11: 9 | B11: 张思思 | C11: =VLOOKUP(B11,[2]Sheet2!$B:$F,5,0) -> 税企服务中心 | D11: =VLOOKUP(B11,[2]Sheet2!$B:$H,7,0) -> B端服务组 | E11: 0.75138889 | F11: 10 | G11: =E11/F11 -> 0.075138889 | J11: 商务法务部 | K11: 0.095138889
A12: 10 | B12: 张权中 | C12: =VLOOKUP(B12,[2]Sheet2!$B:$F,5,0) -> 慧税云服 | D12: =VLOOKUP(B12,[2]Sheet2!$B:$H,7,0) -> 慧税学苑-产品研发组 | E12: 0.65416667 | F12: 10 | G12: =E12/F12 -> 0.065416667 | J12: 资源中心-架构组 | K12: 0.052083333
A13: 11 | B13: 方应广 | C13: =VLOOKUP(B13,[2]Sheet2!$B:$F,5,0) -> 慧税云服 | D13: =VLOOKUP(B13,[2]Sheet2!$B:$H,7,0) -> 慧税学苑-产品研发组 | E13: 0.60277778 | F13: 7 | G13: =E13/F13 -> 0.086111111 | J13: 资源中心-资源组 | K13: 1.1444444
A14: 12 | B14: 巩锡莹 | C14: =VLOOKUP(B14,[2]Sheet2!$B:$F,5,0) -> 税企服务中心 | D14: =VLOOKUP(B14,[2]Sheet2!$B:$H,7,0) -> 资源中心-资源组 | E14: 0.51736111 | F14: 8 | G14: =E14/F14 -> 0.064670139 | J14: 总计 | K14: 16.009028
A15: 13 | B15: 赵秋磊 | C15: =VLOOKUP(B15,[2]Sheet2!$B:$F,5,0) -> 税企服务中心 | D15: =VLOOKUP(B15,[2]Sheet2!$B:$H,7,0) -> B端服务组 | E15: 0.48541667 | F15: 11 | G15: =E15/F15 -> 0.044128788
A16: 14 | B16: 鲁继铎 | C16: =VLOOKUP(B16,[2]Sheet2!$B:$F,5,0) -> 慧税云服 | D16: =VLOOKUP(B16,[2]Sheet2!$B:$H,7,0) -> 慧税学苑-产品研发组 | E16: 0.46736111 | F16: 8 | G16: =E16/F16 -> 0.058420139
A17: 15 | B17: 王连城 | C17: =VLOOKUP(B17,[2]Sheet2!$B:$F,5,0) -> 税企服务中心 | D17: =VLOOKUP(B17,[2]Sheet2!$B:$H,7,0) -> G端服务组 | E17: 0.42638889 | F17: 2 | G17: =E17/F17 -> 0.21319444
A18: 16 | B18: 牟嘉文 | C18: =VLOOKUP(B18,[2]Sheet2!$B:$F,5,0) -> 税企服务中心 | D18: =VLOOKUP(B18,[2]Sheet2!$B:$H,7,0) -> G端服务组 | E18: 0.41666667 | F18: 4 | G18: =E18/F18 -> 0.10416667
A19: 17 | B19: 李冬阳 | C19: =VLOOKUP(B19,[2]Sheet2!$B:$F,5,0) -> 税企服务中心 | D19: =VLOOKUP(B19,[2]Sheet2!$B:$H,7,0) -> 资源中心-资源组 | E19: 0.35763889 | F19: 5 | G19: =E19/F19 -> 0.071527778
A20: 18 | B20: 姜起波 | C20: =VLOOKUP(B20,[2]Sheet2!$B:$F,5,0) -> 税企服务中心 | D20: =VLOOKUP(B20,[2]Sheet2!$B:$H,7,0) -> B端服务组 | E20: 0.33402778 | F20: 2 | G20: =E20/F20 -> 0.16701389
A21: 19 | B21: 焦铄然 | C21: =VLOOKUP(B21,[2]Sheet2!$B:$F,5,0) -> 慧税云服 | D21: =VLOOKUP(B21,[2]Sheet2!$B:$H,7,0) -> 慧税学苑-产品研发组 | E21: 0.30833333 | F21: 5 | G21: =E21/F21 -> 0.061666667
A22: 20 | B22: 孙健 | C22: =VLOOKUP(B22,[2]Sheet2!$B:$F,5,0) -> 慧税云服 | D22: =VLOOKUP(B22,[2]Sheet2!$B:$H,7,0) -> 慧税学苑-运营组 | E22: 0.23055556 | F22: 2 | G22: =E22/F22 -> 0.11527778
A23: 21 | B23: 宝佳 | C23: =VLOOKUP(B23,[2]Sheet2!$B:$F,5,0) -> 税企服务中心 | D23: =VLOOKUP(B23,[2]Sheet2!$B:$H,7,0) -> B端服务组 | E23: 0.22152778 | F23: 3 | G23: =E23/F23 -> 0.073842593
A24: 22 | B24: 张万松 | C24: =VLOOKUP(B24,[2]Sheet2!$B:$F,5,0) -> 税企服务中心 | D24: =VLOOKUP(B24,[2]Sheet2!$B:$H,7,0) -> G端服务组 | E24: 0.16875 | F24: 1 | G24: =E24/F24 -> 0.16875
A25: 23 | B25: 姜颖君 | C25: =VLOOKUP(B25,[2]Sheet2!$B:$F,5,0) -> 税企服务中心 | D25: =VLOOKUP(B25,[2]Sheet2!$B:$H,7,0) -> B端服务组 | E25: 0.16458333 | F25: 2 | G25: =E25/F25 -> 0.082291667
A26: 24 | B26: 张慧艳 | C26: =VLOOKUP(B26,[2]Sheet2!$B:$F,5,0) -> 税企服务中心 | D26: =VLOOKUP(B26,[2]Sheet2!$B:$H,7,0) -> 资源中心-资源组 | E26: 0.1625 | F26: 2 | G26: =E26/F26 -> 0.08125
... A48: 46 | B48: 刘瑶 | C48: =VLOOKUP(B48,[2]Sheet2!$B:$F,5,0) -> 税企服务中心 | D48: =VLOOKUP(B48,[2]Sheet2!$B:$H,7,0) -> B端服务组 | E48: 0.041666667 | F48: 1 | G48: =E48/F48 -> 0.041666667
